Traceback (most recent call last):
  File "test.py", line 7, in <module>
    raise Exception("33");
Exception: 33
